Workbook
Name SegmentaçãoDeDados_ano: #N/A
Name SegmentaçãoDeDados_designacao_produto: #N/A
Name SegmentaçãoDeDados_mês: #N/A

Sheet Analises_Desp
I2: Soma de quantidade_real_produzida
A3: Rótulos de Linha | B3: Total Embalagens Conforme | C3: Total Embalagens Não Conforme | E3: Rótulos de Linha | F3: Soma de custo_desperdicio_eur | G3: Soma de desperdicio_m | I3: =GETPIVOTDATA("Total Embalagens Conforme",$A$3) -> 119905
A4: lascas bacalhau | B4: 119905 | C4: 9540 | E4: lascas bacalhau | F4: 347.25 | G4: 2671.2 | I4: Soma de peso_errado
A5: Total Geral | B5: 119905 | C5: 9540 | E5: Total Geral | F5: 347.25 | G5: 2671.2 | I5: =GETPIVOTDATA("Total Embalagens Não Conforme",$A$3) -> 9540
I6: Soma de custo_desperdicio_eur
I7: =GETPIVOTDATA("custo_desperdicio_eur",$E$3) -> 347.25
I8: Soma de desperdicio_m
I9: =GETPIVOTDATA("Soma de desperdicio_m",$E$3) -> 2671.2
A20: Rótulos de Linha | B20: Soma de custo_desperdicio_eur
A21: lascas bacalhau | B21: 347.25
A22: Total Geral | B22: 347.25
A37: Média de dias_desde_ultima data
A38: 49.571429
A44: Valores
A45: Impressão com defeito/erro | B45: 365
A46: Embalagens danificadas | B46: 523
A47: Peso não conforme | B47: 8652
A61: Soma de custo_desperdicio_eur | B61: Rótulos de Coluna
A62: Rótulos de Linha | B62: 2025 | C62: Total Geral
A63: janeiro | B63: 20.03 | C63: 20.03
A64: fevereiro | B64: 25.48 | C64: 25.48
A65: março | B65: 19.95 | C65: 19.95
A66: abril | B66: 29.34 | C66: 29.34
A67: maio | B67: 39.57 | C67: 39.57
A68: junho | B68: 46.3 | C68: 46.3
A69: julho | B69: 35.85 | C69: 35.85
A70: agosto | B70: 14.19 | C70: 14.19
A71: setembro | B71: 58.06 | C71: 58.06
A72: outubro | B72: 17.76 | C72: 17.76
A73: novembro | B73: 32.13 | C73: 32.13
A74: dezembro | B74: 8.59 | C74: 8.59
A75: Total Geral | B75: 347.25 | C75: 347.25
A80: Rótulos de Linha | B80: Média de desperdicio_pct
A81: 0 | B81: 0.0354
A82: 1 | B82: 0.0636
A83: 7 | B83: 0.0491
A84: 8 | B84: 0.06265
A85: 10 | B85: 0.057
A86: 12 | B86: 0.0628
A87: 13 | B87: 0.0661
...

Sheet Dashboard

Sheet Dashboard (2)

Sheet Dashboard (3)

Sheet Dashboard (4)

Sheet Fato_Producao
A1: data | B1: referencia | C1: designacao_produto | D1: contador_maquina | E1: quantidade_real_produzida | F1: desperdicio_pct | G1: desperdicio_m | H1: embalagens_danificadas | I1: peso_errado | J1: impressao | K1: total_embalagens_nao_conforme | L1: data_ultima_revisao | M1: dias_desde_revisao | N1: custo_desperdicio_eur | O1: mês | P1: ano | Q1: dias_desde_ultima data | R1: flag_avaria_erro
A2: 2023-10-01 | B2: 45513 | C2: =VLOOKUP(Fato_Producao[[#This Row],[referencia]], Dim_Produtos!A:B,2,FALSE) -> filete pescada | D2: 2362 | E2: 2230 | F2: 0.0559 | G2: 42.24 | H2: 3 | I2: 126 | J2: 3 | K2: =Fato_Producao[[#This Row],[embalagens_danificadas]]+Fato_Producao[[#This Row],[peso_errado]]+Fato_Producao[[#This Row],[impressao]] -> 132 | L2: 2023-09-16 | M2: 15 | N2: 5.49 | O2: =TEXT(A2, "mmmm") -> outubro | P2: =YEAR(A2) -> 2023 | Q2: =IF(M3 >= M2, "", M2) | R2: Nao
A3: 2023-10-02 | B3: 45501 | C3: =VLOOKUP(Fato_Producao[[#This Row],[referencia]], Dim_Produtos!A:B,2,FALSE) -> pescada posta cozer | D3: 2400 | E3: 2249 | F3: 0.0629 | G3: 48.32 | H3: 5 | I3: 144 | J3: 2 | K3: =Fato_Producao[[#This Row],[embalagens_danificadas]]+Fato_Producao[[#This Row],[peso_errado]]+Fato_Producao[[#This Row],[impressao]] -> 151 | L3: 2023-09-16 | M3: 16 | N3: 6.76 | O3: =TEXT(A3, "mmmm") -> outubro | P3: =YEAR(A3) -> 2023 | Q3: =IF(M4 >= M3, "", M3) | R3: Nao
A4: 2023-10-02 | B4: 45504 | C4: =VLOOKUP(Fato_Producao[[#This Row],[referencia]], Dim_Produtos!A:B,2,FALSE) -> pescada posta fritar | D4: 3163 | E4: 2938 | F4: 0.0711 | G4: 72 | H4: 8 | I4: 214 | J4: 3 | K4: =Fato_Producao[[#This Row],[embalagens_danificadas]]+Fato_Producao[[#This Row],[peso_errado]]+Fato_Producao[[#This Row],[impressao]] -> 225 | L4: 2023-09-16 | M4: 16 | N4: 10.08 | O4: =TEXT(A4, "mmmm") -> outubro | P4: =YEAR(A4) -> 2023 | Q4: =IF(M5 >= M4, "", M4) | R4: Nao
A5: 2023-10-03 | B5: 45501 | C5: =VLOOKUP(Fato_Producao[[#This Row],[referencia]], Dim_Produtos!A:B,2,FALSE) -> pescada posta cozer | D5: 2821 | E5: 2671 | F5: 0.0532 | G5: 48 | H5: 7 | I5: 141 | J5: 2 | K5: =Fato_Producao[[#This Row],[embalagens_danificadas]]+Fato_Producao[[#This Row],[peso_errado]]+Fato_Producao[[#This Row],[impressao]] -> 150 | L5: 2023-09-16 | M5: 17 | N5: 6.72 | O5: =TEXT(A5, "mmmm") -> outubro | P5: =YEAR(A5) -> 2023 | Q5: =IF(M6 >= M5, "", M5) | R5: Nao
A6: 2023-10-04 | B6: 45509 | C6: =VLOOKUP(Fato_Producao[[#This Row],[referencia]], Dim_Produtos!A:B,2,FALSE) -> lascas bacalhau | D6: 3379 | E6: 3124 | F6: 0.0755 | G6: 71.4 | H6: 17 | I6: 235 | J6: 3 | K6: =Fato_Producao[[#This Row],[embalagens_danificadas]]+Fato_Producao[[#This Row],[peso_errado]]+Fato_Producao[[#This Row],[impressao]] -> 255 | L6: 2023-09-16 | M6: 18 | N6: 9.28 | O6: =TEXT(A6, "mmmm") -> outubro | P6: =YEAR(A6) -> 2023 | Q6: =IF(M7 >= M6, "", M6) | R6: Nao
A7: 2023-10-04 | B7: 45507 | C7: =VLOOKUP(Fato_Producao[[#This Row],[referencia]], Dim_Produtos!A:B,2,FALSE) -> salmao posta | D7: 2137 | E7: 2012 | F7: 0.0585 | G7: 43.75 | H7: 4 | I7: 117 | J7: 4 | K7: =Fato_Producao[[#This Row],[embalagens_danificadas]]+Fato_Producao[[#This Row],[peso_errado]]+Fato_Producao[[#This Row],[impressao]] -> 125 | L7: 2023-09-16 | M7: 18 | N7: 7 | O7: =TEXT(A7, "mmmm") -> outubro | P7: =YEAR(A7) -> 2023 | Q7: =IF(M8 >= M7, "", M7) | R7: Nao
A8: 2023-10-05 | B8: 45512 | C8: =VLOOKUP(Fato_Producao[[#This Row],[referencia]], Dim_Produtos!A:B,2,FALSE) -> red-fish posta | D8: 2980 | E8: 2790 | F8: 0.0638 | G8: 64.6 | H8: 8 | I8: 180 | J8: 2 | K8: =Fato_Producao[[#This Row],[embalagens_danificadas]]+Fato_Producao[[#This Row],[peso_errado]]+Fato_Producao[[#This Row],[impressao]] -> 190 | L8: 2023-09-16 | M8: 19 | N8: 9.04 | O8: =TEXT(A8, "mmmm") -> outubro | P8: =YEAR(A8) -> 2023 | Q8: =IF(M9 >= M8, "", M8) | R8: Nao
A9: 2023-10-05 | B9: 45506 | C9: =VLOOKUP(Fato_Producao[[#This Row],[referencia]], Dim_Produtos!A:B,2,FALSE) -> perca posta | D9: 3888 | E9: 3629 | F9: 0.0666 | G9: 90.65 | H9: 7 | I9: 247 | J9: 5 | K9: =Fato_Producao[[#This Row],[embalagens_danificadas]]+Fato_Producao[[#This Row],[peso_errado]]+Fato_Producao[[#This Row],[impressao]] -> 259 | L9: 2023-09-16 | M9: 19 | N9: 13.6 | O9: =TEXT(A9, "mmmm") -> outubro | P9: =YEAR(A9) -> 2023 | Q9: =IF(M10 >= M9, "", M9) | R9: Nao
A10: 2023-10-06 | B10: 45506 | C10: =VLOOKUP(Fato_Producao[[#This Row],[referencia]], Dim_Produtos!A:B,2,FALSE) -> perca posta | D10: 3551 | E10: 3309 | F10: 0.0681 | G10: 84.7 | H10: 11 | I10: 227 | J10: 4 | K10: =Fato_Producao[[#This Row],[embalagens_danificadas]]+Fato_Producao[[#This Row],[peso_errado]]+Fato_Producao[[#This Row],[impressao]] -> 242 | L10: 2023-09-16 | M10: 20 | N10: 12.71 | O10: =TEXT(A10, "mmmm") -> outubro | P10: =YEAR(A10) -> 2023 | Q10: =IF(M11 >= M10, "", M10) | R10: Nao
A11: 2023-10-07 | B11: 45502 | C11: =VLOOKUP(Fato_Producao[[#This Row],[referencia]], Dim_Produtos!A:B,2,FALSE) -> carapau pelim | D11: 2828 | E11: 2580 | F11: 0.0877 | G11: 74.4 | H11: 72 | I11: 170 | J11: 6 | K11: =Fato_Producao[[#This Row],[embalagens_danificadas]]+Fato_Producao[[#This Row],[peso_errado]]+Fato_Producao[[#This Row],[impressao]] -> 248 | L11: 2023-09-16 | M11: 21 | N11: 9.67 | O11: =TEXT(A11, "mmmm") -> outubro | P11: =YEAR(A11) -> 2023 | Q11: =IF(M12 >= M11, "", M11) | R11: Nao
A12: 2023-10-07 | B12: 45508 | C12: =VLOOKUP(Fato_Producao[[#This Row],[referencia]], Dim_Produtos!A:B,2,FALSE) -> lula suja | D12: 2006 | E12: 1828 | F12: 0.0887 | G12: 56.96 | H12: 15 | I12: 159 | J12: 4 | K12: =Fato_Producao[[#This Row],[embalagens_danificadas]]+Fato_Producao[[#This Row],[peso_errado]]+Fato_Producao[[#This Row],[impressao]] -> 178 | L12: 2023-09-16 | M12: 21 | N12: 7.97 | O12: =TEXT(A12, "mmmm") -> outubro | P12: =YEAR(A12) -> 2023 | Q12: =IF(M13 >= M12, "", M12) | R12: Nao
A13: 2023-10-08 | B13: 45503 | C13: =VLOOKUP(Fato_Producao[[#This Row],[referencia]], Dim_Produtos!A:B,2,FALSE) -> sardinha pequena | D13: 3557 | E13: 3305 | F13: 0.0708 | G13: 65.52 | H13: 10 | I13: 237 | J13: 5 | K13: =Fato_Producao[[#This Row],[embalagens_danificadas]]+Fato_Producao[[#This Row],[peso_errado]]+Fato_Producao[[#This Row],[impressao]] -> 252 | L13: 2023-09-16 | M13: 22 | N13: 7.21 | O13: =TEXT(A13, "mmmm") -> outubro | P13: =YEAR(A13) -> 2023 | Q13: =IF(M14 >= M13, "", M13) | R13: Nao
... A1793: 2026-09-30 | B1793: 45504 | C1793: =VLOOKUP(Fato_Producao[[#This Row],[referencia]], Dim_Produtos!A:B,2,FALSE) -> pescada posta fritar | D1793: 3255 | E1793: 2960 | F1793: 0.0906 | G1793: 94.4 | H1793: 21 | I1793: 271 | J1793: 3 | K1793: =Fato_Producao[[#This Row],[embalagens_danificadas]]+Fato_Producao[[#This Row],[peso_errado]]+Fato_Producao[[#This Row],[impressao]] -> 295 | L1793: 2026-08-19 | M1793: 42 | N1793: 13.22 | O1793: =TEXT(A1793, "mmmm") -> setembro | P1793: =YEAR(A1793) -> 2026 | Q1793: =IF(M1794 >= M1793, "", M1793) -> 42 | R1793: Nao

Sheet Dim_Produtos
A1: referencia | B1: designacao | C1: tipo | D1: tamanho | E1: peso_alvo | F1: tamanho_embalagem | G1: custo_metro_filme
A2: 45513 | B2: filete pescada | C2: inteiro | D2: L | E2: 1000 | F2: 0.32 | G2: 0.13
A3: 45501 | B3: pescada posta cozer | C3: posta | D3: M | E3: 1000 | F3: 0.32 | G3: 0.14
A4: 45504 | B4: pescada posta fritar | C4: posta | D4: M | E4: 1000 | F4: 0.32 | G4: 0.14
A5: 45501 | B5: pescada posta cozer | C5: posta | D5: M | E5: 1000 | F5: 0.32 | G5: 0.14
A6: 45509 | B6: lascas bacalhau | C6: posta | D6: S | E6: 500 | F6: 0.28 | G6: 0.13
A7: 45507 | B7: salmao posta | C7: posta | D7: L | E7: 1000 | F7: 0.35 | G7: 0.16
A8: 45512 | B8: red-fish posta | C8: posta | D8: L | E8: 1000 | F8: 0.34 | G8: 0.14
A9: 45506 | B9: perca posta | C9: posta | D9: L | E9: 1000 | F9: 0.35 | G9: 0.15
A10: 45506 | B10: perca posta | C10: posta | D10: L | E10: 1000 | F10: 0.35 | G10: 0.15
A11: 45502 | B11: carapau pelim | C11: inteiro | D11: S | E11: 800 | F11: 0.3 | G11: 0.13
A12: 45508 | B12: lula suja | C12: inteiro | D12: S | E12: 1000 | F12: 0.32 | G12: 0.14
A13: 45503 | B13: sardinha pequena | C13: inteiro | D13: S | E13: 500 | F13: 0.26 | G13: 0.11
... A1793: 45504 | B1793: pescada posta fritar | C1793: posta | D1793: M | E1793: 1000 | F1793: 0.32 | G1793: 0.14

Sheet Dim_Calendario
A1: Data | B1: Ano | C1: MesNum | D1: NomeMes | E1: AnoMes
A2: 2023-10-01 | B2: =YEAR(A2) -> 2023 | C2: =MONTH(A2) -> 10 | D2: =TEXT(A2, "mmmm") -> outubro | E2: =TEXT(A2, "aaaa-mm") -> 2023-10
A3: 2023-10-02 | B3: =YEAR(A3) -> 2023 | C3: =MONTH(A3) -> 10 | D3: =TEXT(A3, "mmmm") -> outubro | E3: =TEXT(A3, "aaaa-mm") -> 2023-10
A4: 2023-10-03 | B4: =YEAR(A4) -> 2023 | C4: =MONTH(A4) -> 10 | D4: =TEXT(A4, "mmmm") -> outubro | E4: =TEXT(A4, "aaaa-mm") -> 2023-10
A5: 2023-10-04 | B5: =YEAR(A5) -> 2023 | C5: =MONTH(A5) -> 10 | D5: =TEXT(A5, "mmmm") -> outubro | E5: =TEXT(A5, "aaaa-mm") -> 2023-10
A6: 2023-10-05 | B6: =YEAR(A6) -> 2023 | C6: =MONTH(A6) -> 10 | D6: =TEXT(A6, "mmmm") -> outubro | E6: =TEXT(A6, "aaaa-mm") -> 2023-10
A7: 2023-10-06 | B7: =YEAR(A7) -> 2023 | C7: =MONTH(A7) -> 10 | D7: =TEXT(A7, "mmmm") -> outubro | E7: =TEXT(A7, "aaaa-mm") -> 2023-10
A8: 2023-10-07 | B8: =YEAR(A8) -> 2023 | C8: =MONTH(A8) -> 10 | D8: =TEXT(A8, "mmmm") -> outubro | E8: =TEXT(A8, "aaaa-mm") -> 2023-10
A9: 2023-10-08 | B9: =YEAR(A9) -> 2023 | C9: =MONTH(A9) -> 10 | D9: =TEXT(A9, "mmmm") -> outubro | E9: =TEXT(A9, "aaaa-mm") -> 2023-10
A10: 2023-10-09 | B10: =YEAR(A10) -> 2023 | C10: =MONTH(A10) -> 10 | D10: =TEXT(A10, "mmmm") -> outubro | E10: =TEXT(A10, "aaaa-mm") -> 2023-10
A11: 2023-10-10 | B11: =YEAR(A11) -> 2023 | C11: =MONTH(A11) -> 10 | D11: =TEXT(A11, "mmmm") -> outubro | E11: =TEXT(A11, "aaaa-mm") -> 2023-10
A12: 2023-10-11 | B12: =YEAR(A12) -> 2023 | C12: =MONTH(A12) -> 10 | D12: =TEXT(A12, "mmmm") -> outubro | E12: =TEXT(A12, "aaaa-mm") -> 2023-10
A13: 2023-10-12 | B13: =YEAR(A13) -> 2023 | C13: =MONTH(A13) -> 10 | D13: =TEXT(A13, "mmmm") -> outubro | E13: =TEXT(A13, "aaaa-mm") -> 2023-10
... A1097: 2026-09-30 | B1097: =YEAR(A1097) -> 2026 | C1097: =MONTH(A1097) -> 9 | D1097: =TEXT(A1097, "mmmm") -> setembro | E1097: =TEXT(A1097, "aaaa-mm") -> 2026-09
